2020-10-20 12:18:28,879 - Shuake.py[line:273] - ERROR: 
Traceback (most recent call last):
  File "D:/bin/chaoxing_auto_Shuake/com/main/Shuake.py", line 193, in shuake
    if cardInfo['type'] == "video":
KeyError: 'type'
2020-10-20 13:14:55,457 - Shuake.py[line:273] - ERROR: 
Traceback (most recent call last):
  File "D:/bin/chaoxing_auto_Shuake/com/main/Shuake.py", line 193, in shuake
    if cardInfo['type'] == "video":
KeyError: 'type'
2020-10-20 13:15:27,584 - Shuake.py[line:273] - ERROR: 
Traceback (most recent call last):
  File "D:/bin/chaoxing_auto_Shuake/com/main/Shuake.py", line 193, in shuake
    if cardInfo['type'] == "video":
KeyError: 'type'
2020-10-20 15:54:35,277 - Shuake.py[line:276] - ERROR: 
Traceback (most recent call last):
  File "D:/bin/chaoxing_auto_Shuake/com/main/Shuake.py", line 243, in shuake
    chapters,lastChapter = self.get_chapters_info(pageInfo, cardInfo, reportInfo)
ValueError: not enough values to unpack (expected 2, got 0)
2020-10-20 19:20:55,550 - Shuake.py[line:278] - ERROR: 
Traceback (most recent call last):
  File "D:\ProgramData\Anaconda3\envs\spy\lib\site-packages\urllib3\connection.py", line 171, in _new_conn
    (self._dns_host, self.port), self.timeout, **extra_kw)
  File "D:\ProgramData\Anaconda3\envs\spy\lib\site-packages\urllib3\util\connection.py", line 56, in create_connection
    for res in socket.getaddrinfo(host, port, family, socket.SOCK_STREAM):
  File "D:\ProgramData\Anaconda3\envs\spy\lib\socket.py", line 748, in getaddrinfo
    for res in _socket.getaddrinfo(host, port, family, type, proto, flags):
socket.gaierror: [Errno 11001] getaddrinfo failed

During handling of the above exception, another exception occurred:

Traceback (most recent call last):
  File "D:\ProgramData\Anaconda3\envs\spy\lib\site-packages\urllib3\connectionpool.py", line 600, in urlopen
    chunked=chunked)
  File "D:\ProgramData\Anaconda3\envs\spy\lib\site-packages\urllib3\connectionpool.py", line 343, in _make_request
    self._validate_conn(conn)
  File "D:\ProgramData\Anaconda3\envs\spy\lib\site-packages\urllib3\connectionpool.py", line 849, in _validate_conn
    conn.connect()
  File "D:\ProgramData\Anaconda3\envs\spy\lib\site-packages\urllib3\connection.py", line 314, in connect
    conn = self._new_conn()
  File "D:\ProgramData\Anaconda3\envs\spy\lib\site-packages\urllib3\connection.py", line 180, in _new_conn
    self, "Failed to establish a new connection: %s" % e)
urllib3.exceptions.NewConnectionError: <urllib3.connection.VerifiedHTTPSConnection object at 0x000001A81C7FE2E8>: Failed to establish a new connection: [Errno 11001] getaddrinfo failed

During handling of the above exception, another exception occurred:

Traceback (most recent call last):
  File "D:\ProgramData\Anaconda3\envs\spy\lib\site-packages\requests\adapters.py", line 445, in send
    timeout=timeout
  File "D:\ProgramData\Anaconda3\envs\spy\lib\site-packages\urllib3\connectionpool.py", line 638, in urlopen
    _stacktrace=sys.exc_info()[2])
  File "D:\ProgramData\Anaconda3\envs\spy\lib\site-packages\urllib3\util\retry.py", line 398, in increment
    raise MaxRetryError(_pool, url, error or ResponseError(cause))
urllib3.exceptions.MaxRetryError: HTTPSConnectionPool(host='special.zhexuezj.cn', port=443): Max retries exceeded with url: /special/course/addUserPoint?courseId=215091538&chapterId=342714643&point=3&_from_=215091538_33359344_59414233_3dd8a5e5286c3f8d89a3b0f0b1a7246a&rtag=340728584_134434924_read-214228146 (Caused by NewConnectionError('<urllib3.connection.VerifiedHTTPSConnection object at 0x000001A81C7FE2E8>: Failed to establish a new connection: [Errno 11001] getaddrinfo failed'))

During handling of the above exception, another exception occurred:

Traceback (most recent call last):
  File "D:/bin/chaoxing_auto_Shuake/com/main/Shuake.py", line 271, in shuake
    'https://special.zhexuezj.cn/special/course/addUserPoint', params=params)
  File "D:\ProgramData\Anaconda3\envs\spy\lib\site-packages\requests\sessions.py", line 525, in get
    return self.request('GET', url, **kwargs)
  File "D:\ProgramData\Anaconda3\envs\spy\lib\site-packages\requests\sessions.py", line 512, in request
    resp = self.send(prep, **send_kwargs)
  File "D:\ProgramData\Anaconda3\envs\spy\lib\site-packages\requests\sessions.py", line 622, in send
    r = adapter.send(request, **kwargs)
  File "D:\ProgramData\Anaconda3\envs\spy\lib\site-packages\requests\adapters.py", line 513, in send
    raise ConnectionError(e, request=request)
requests.exceptions.ConnectionError: HTTPSConnectionPool(host='special.zhexuezj.cn', port=443): Max retries exceeded with url: /special/course/addUserPoint?courseId=215091538&chapterId=342714643&point=3&_from_=215091538_33359344_59414233_3dd8a5e5286c3f8d89a3b0f0b1a7246a&rtag=340728584_134434924_read-214228146 (Caused by NewConnectionError('<urllib3.connection.VerifiedHTTPSConnection object at 0x000001A81C7FE2E8>: Failed to establish a new connection: [Errno 11001] getaddrinfo failed'))
2020-10-20 19:29:13,734 - Shuake.py[line:278] - ERROR: 
Traceback (most recent call last):
  File "D:\ProgramData\Anaconda3\envs\spy\lib\site-packages\urllib3\connection.py", line 171, in _new_conn
    (self._dns_host, self.port), self.timeout, **extra_kw)
  File "D:\ProgramData\Anaconda3\envs\spy\lib\site-packages\urllib3\util\connection.py", line 56, in create_connection
    for res in socket.getaddrinfo(host, port, family, socket.SOCK_STREAM):
  File "D:\ProgramData\Anaconda3\envs\spy\lib\socket.py", line 748, in getaddrinfo
    for res in _socket.getaddrinfo(host, port, family, type, proto, flags):
socket.gaierror: [Errno 11001] getaddrinfo failed

During handling of the above exception, another exception occurred:

Traceback (most recent call last):
  File "D:\ProgramData\Anaconda3\envs\spy\lib\site-packages\urllib3\connectionpool.py", line 600, in urlopen
    chunked=chunked)
  File "D:\ProgramData\Anaconda3\envs\spy\lib\site-packages\urllib3\connectionpool.py", line 343, in _make_request
    self._validate_conn(conn)
  File "D:\ProgramData\Anaconda3\envs\spy\lib\site-packages\urllib3\connectionpool.py", line 849, in _validate_conn
    conn.connect()
  File "D:\ProgramData\Anaconda3\envs\spy\lib\site-packages\urllib3\connection.py", line 314, in connect
    conn = self._new_conn()
  File "D:\ProgramData\Anaconda3\envs\spy\lib\site-packages\urllib3\connection.py", line 180, in _new_conn
    self, "Failed to establish a new connection: %s" % e)
urllib3.exceptions.NewConnectionError: <urllib3.connection.VerifiedHTTPSConnection object at 0x000001A81C83F358>: Failed to establish a new connection: [Errno 11001] getaddrinfo failed

During handling of the above exception, another exception occurred:

Traceback (most recent call last):
  File "D:\ProgramData\Anaconda3\envs\spy\lib\site-packages\requests\adapters.py", line 445, in send
    timeout=timeout
  File "D:\ProgramData\Anaconda3\envs\spy\lib\site-packages\urllib3\connectionpool.py", line 638, in urlopen
    _stacktrace=sys.exc_info()[2])
  File "D:\ProgramData\Anaconda3\envs\spy\lib\site-packages\urllib3\util\retry.py", line 398, in increment
    raise MaxRetryError(_pool, url, error or ResponseError(cause))
urllib3.exceptions.MaxRetryError: HTTPSConnectionPool(host='special.zhexuezj.cn', port=443): Max retries exceeded with url: /special/course/addUserPoint?courseId=215091538&chapterId=342714560&point=18&_from_=215091538_33359344_109852603_3dd8a5e5286c3f8d89a3b0f0b1a7246a&rtag=340728584_134434079_read-214228146 (Caused by NewConnectionError('<urllib3.connection.VerifiedHTTPSConnection object at 0x000001A81C83F358>: Failed to establish a new connection: [Errno 11001] getaddrinfo failed'))

During handling of the above exception, another exception occurred:

Traceback (most recent call last):
  File "D:/bin/chaoxing_auto_Shuake/com/main/Shuake.py", line 271, in shuake
    'https://special.zhexuezj.cn/special/course/addUserPoint', params=params)
  File "D:\ProgramData\Anaconda3\envs\spy\lib\site-packages\requests\sessions.py", line 525, in get
    return self.request('GET', url, **kwargs)
  File "D:\ProgramData\Anaconda3\envs\spy\lib\site-packages\requests\sessions.py", line 512, in request
    resp = self.send(prep, **send_kwargs)
  File "D:\ProgramData\Anaconda3\envs\spy\lib\site-packages\requests\sessions.py", line 622, in send
    r = adapter.send(request, **kwargs)
  File "D:\ProgramData\Anaconda3\envs\spy\lib\site-packages\requests\adapters.py", line 513, in send
    raise ConnectionError(e, request=request)
requests.exceptions.ConnectionError: HTTPSConnectionPool(host='special.zhexuezj.cn', port=443): Max retries exceeded with url: /special/course/addUserPoint?courseId=215091538&chapterId=342714560&point=18&_from_=215091538_33359344_109852603_3dd8a5e5286c3f8d89a3b0f0b1a7246a&rtag=340728584_134434079_read-214228146 (Caused by NewConnectionError('<urllib3.connection.VerifiedHTTPSConnection object at 0x000001A81C83F358>: Failed to establish a new connection: [Errno 11001] getaddrinfo failed'))
2020-10-20 20:41:45,438 - Shuake.py[line:58] - ERROR: 
Traceback (most recent call last):
  File "D:/bin/chaoxing_auto_Shuake/com/main/Shuake.py", line 55, in login
    self.puid = re.search(r"puid\":(.*?),", resp).group(1)
AttributeError: 'NoneType' object has no attribute 'group'
