2020-10-19 10:42:48,322 - Shuake.py[line:358] - INFO: 运行
2020-10-19 10:43:48,898 - Shuake.py[line:358] - INFO: 运行
2020-10-19 11:32:17,928 - Shuake.py[line:358] - INFO: 运行
2020-10-19 12:25:51,358 - Shuake.py[line:326] - ERROR: 
Traceback (most recent call last):
  File "D:/bin/chaoxing_auto_Shuake/com/main/Shuake.py", line 313, in get_chapters_info
    chapters_a = chapters_lxml.find_all(name="a")
AttributeError: 'NoneType' object has no attribute 'find_all'
2020-10-19 12:25:51,360 - Shuake.py[line:327] - INFO: 18740455867	获取chapter_info 失败
2020-10-19 12:25:51,360 - Shuake.py[line:270] - ERROR: 
Traceback (most recent call last):
  File "D:/bin/chaoxing_auto_Shuake/com/main/Shuake.py", line 241, in shuake
    for chapter in chapters:
TypeError: 'bool' object is not iterable
2020-10-19 12:25:51,361 - Shuake.py[line:271] - INFO: 18740455867	刷课意外
2020-10-19 12:30:22,470 - Shuake.py[line:326] - ERROR: 
Traceback (most recent call last):
  File "D:/bin/chaoxing_auto_Shuake/com/main/Shuake.py", line 313, in get_chapters_info
    chapters_a = chapters_lxml.find_all(name="a")
AttributeError: 'NoneType' object has no attribute 'find_all'
2020-10-19 12:30:22,470 - Shuake.py[line:327] - INFO: 18182699011	获取chapter_info 失败
2020-10-19 12:30:22,471 - Shuake.py[line:270] - ERROR: 
Traceback (most recent call last):
  File "D:/bin/chaoxing_auto_Shuake/com/main/Shuake.py", line 241, in shuake
    for chapter in chapters:
TypeError: 'bool' object is not iterable
2020-10-19 12:30:22,471 - Shuake.py[line:271] - INFO: 18182699011	刷课意外
2020-10-19 12:30:26,459 - Shuake.py[line:326] - ERROR: 
Traceback (most recent call last):
  File "D:/bin/chaoxing_auto_Shuake/com/main/Shuake.py", line 313, in get_chapters_info
    chapters_a = chapters_lxml.find_all(name="a")
AttributeError: 'NoneType' object has no attribute 'find_all'
2020-10-19 12:30:26,460 - Shuake.py[line:327] - INFO: 15970198033	获取chapter_info 失败
2020-10-19 12:30:26,460 - Shuake.py[line:270] - ERROR: 
Traceback (most recent call last):
  File "D:/bin/chaoxing_auto_Shuake/com/main/Shuake.py", line 241, in shuake
    for chapter in chapters:
TypeError: 'bool' object is not iterable
2020-10-19 12:30:26,460 - Shuake.py[line:271] - INFO: 15970198033	刷课意外
2020-10-19 12:36:14,987 - Shuake.py[line:326] - ERROR: 
Traceback (most recent call last):
  File "D:/bin/chaoxing_auto_Shuake/com/main/Shuake.py", line 313, in get_chapters_info
    chapters_a = chapters_lxml.find_all(name="a")
AttributeError: 'NoneType' object has no attribute 'find_all'
2020-10-19 12:36:14,988 - Shuake.py[line:327] - INFO: 17561925661	获取chapter_info 失败
2020-10-19 12:36:14,988 - Shuake.py[line:270] - ERROR: 
Traceback (most recent call last):
  File "D:/bin/chaoxing_auto_Shuake/com/main/Shuake.py", line 241, in shuake
    for chapter in chapters:
TypeError: 'bool' object is not iterable
2020-10-19 12:36:14,988 - Shuake.py[line:271] - INFO: 17561925661	刷课意外
2020-10-19 13:30:08,156 - Shuake.py[line:326] - ERROR: 
Traceback (most recent call last):
  File "D:/bin/chaoxing_auto_Shuake/com/main/Shuake.py", line 313, in get_chapters_info
    chapters_a = chapters_lxml.find_all(name="a")
AttributeError: 'NoneType' object has no attribute 'find_all'
2020-10-19 13:30:08,156 - Shuake.py[line:327] - INFO: 18845142702	获取chapter_info 失败
2020-10-19 13:30:08,157 - Shuake.py[line:270] - ERROR: 
Traceback (most recent call last):
  File "D:/bin/chaoxing_auto_Shuake/com/main/Shuake.py", line 241, in shuake
    for chapter in chapters:
TypeError: 'bool' object is not iterable
2020-10-19 13:30:08,157 - Shuake.py[line:271] - INFO: 18845142702	刷课意外
2020-10-19 13:44:59,910 - Shuake.py[line:358] - INFO: 运行
2020-10-19 13:47:21,377 - Shuake.py[line:326] - ERROR: 
Traceback (most recent call last):
  File "D:/bin/chaoxing_auto_Shuake/com/main/Shuake.py", line 313, in get_chapters_info
    chapters_a = chapters_lxml.find_all(name="a")
AttributeError: 'NoneType' object has no attribute 'find_all'
2020-10-19 13:47:21,378 - Shuake.py[line:327] - INFO: 18740455867	获取chapter_info 失败
2020-10-19 13:47:21,378 - Shuake.py[line:270] - ERROR: 
Traceback (most recent call last):
  File "D:/bin/chaoxing_auto_Shuake/com/main/Shuake.py", line 241, in shuake
    for chapter in chapters:
TypeError: 'bool' object is not iterable
2020-10-19 13:47:21,379 - Shuake.py[line:271] - INFO: 18740455867	刷课意外
2020-10-19 13:50:33,032 - Shuake.py[line:326] - ERROR: 
Traceback (most recent call last):
  File "D:/bin/chaoxing_auto_Shuake/com/main/Shuake.py", line 313, in get_chapters_info
    chapters_a = chapters_lxml.find_all(name="a")
AttributeError: 'NoneType' object has no attribute 'find_all'
2020-10-19 13:50:33,033 - Shuake.py[line:327] - INFO: 15970198033	获取chapter_info 失败
2020-10-19 13:50:33,033 - Shuake.py[line:270] - ERROR: 
Traceback (most recent call last):
  File "D:/bin/chaoxing_auto_Shuake/com/main/Shuake.py", line 241, in shuake
    for chapter in chapters:
TypeError: 'bool' object is not iterable
2020-10-19 13:50:33,033 - Shuake.py[line:271] - INFO: 15970198033	刷课意外
2020-10-19 13:51:49,847 - Shuake.py[line:326] - ERROR: 
Traceback (most recent call last):
  File "D:/bin/chaoxing_auto_Shuake/com/main/Shuake.py", line 313, in get_chapters_info
    chapters_a = chapters_lxml.find_all(name="a")
AttributeError: 'NoneType' object has no attribute 'find_all'
2020-10-19 13:51:49,848 - Shuake.py[line:327] - INFO: 18182699011	获取chapter_info 失败
2020-10-19 13:51:49,848 - Shuake.py[line:270] - ERROR: 
Traceback (most recent call last):
  File "D:/bin/chaoxing_auto_Shuake/com/main/Shuake.py", line 241, in shuake
    for chapter in chapters:
TypeError: 'bool' object is not iterable
2020-10-19 13:51:49,848 - Shuake.py[line:271] - INFO: 18182699011	刷课意外
2020-10-19 13:53:02,152 - Shuake.py[line:326] - ERROR: 
Traceback (most recent call last):
  File "D:/bin/chaoxing_auto_Shuake/com/main/Shuake.py", line 313, in get_chapters_info
    chapters_a = chapters_lxml.find_all(name="a")
AttributeError: 'NoneType' object has no attribute 'find_all'
2020-10-19 13:53:02,152 - Shuake.py[line:327] - INFO: 18845142702	获取chapter_info 失败
2020-10-19 13:53:02,152 - Shuake.py[line:270] - ERROR: 
Traceback (most recent call last):
  File "D:/bin/chaoxing_auto_Shuake/com/main/Shuake.py", line 241, in shuake
    for chapter in chapters:
TypeError: 'bool' object is not iterable
2020-10-19 13:53:02,153 - Shuake.py[line:271] - INFO: 18845142702	刷课意外
2020-10-19 13:53:27,386 - Shuake.py[line:326] - ERROR: 
Traceback (most recent call last):
  File "D:/bin/chaoxing_auto_Shuake/com/main/Shuake.py", line 313, in get_chapters_info
    chapters_a = chapters_lxml.find_all(name="a")
AttributeError: 'NoneType' object has no attribute 'find_all'
2020-10-19 13:53:27,386 - Shuake.py[line:327] - INFO: 17561925661	获取chapter_info 失败
2020-10-19 13:53:27,387 - Shuake.py[line:270] - ERROR: 
Traceback (most recent call last):
  File "D:/bin/chaoxing_auto_Shuake/com/main/Shuake.py", line 241, in shuake
    for chapter in chapters:
TypeError: 'bool' object is not iterable
2020-10-19 13:53:27,387 - Shuake.py[line:271] - INFO: 17561925661	刷课意外
2020-10-19 15:47:47,596 - Shuake.py[line:358] - INFO: 运行
2020-10-19 15:48:18,529 - Shuake.py[line:326] - ERROR: 
Traceback (most recent call last):
  File "D:/bin/chaoxing_auto_Shuake/com/main/Shuake.py", line 313, in get_chapters_info
    chapters_a = chapters_lxml.find_all(name="a")
AttributeError: 'NoneType' object has no attribute 'find_all'
2020-10-19 15:48:18,530 - Shuake.py[line:327] - INFO: 18740455867	获取chapter_info 失败
2020-10-19 15:49:04,096 - Shuake.py[line:326] - ERROR: 
Traceback (most recent call last):
  File "D:/bin/chaoxing_auto_Shuake/com/main/Shuake.py", line 313, in get_chapters_info
    chapters_a = chapters_lxml.find_all(name="a")
AttributeError: 'NoneType' object has no attribute 'find_all'
2020-10-19 15:49:04,097 - Shuake.py[line:327] - INFO: 15970198033	获取chapter_info 失败
2020-10-19 15:49:50,036 - Shuake.py[line:358] - INFO: 运行
2020-10-19 15:51:00,449 - Shuake.py[line:326] - INFO: 
Traceback (most recent call last):
  File "D:/bin/chaoxing_auto_Shuake/com/main/Shuake.py", line 313, in get_chapters_info
    chapters_a = chapters_lxml.find_all(name="a")
AttributeError: 'NoneType' object has no attribute 'find_all'
2020-10-19 15:51:00,450 - Shuake.py[line:327] - INFO: 18740455867	获取chapter_info 失败
2020-10-19 15:51:06,343 - Shuake.py[line:326] - INFO: 
Traceback (most recent call last):
  File "D:/bin/chaoxing_auto_Shuake/com/main/Shuake.py", line 313, in get_chapters_info
    chapters_a = chapters_lxml.find_all(name="a")
AttributeError: 'NoneType' object has no attribute 'find_all'
2020-10-19 15:51:06,343 - Shuake.py[line:327] - INFO: 15970198033	获取chapter_info 失败
2020-10-19 15:51:51,700 - Shuake.py[line:326] - INFO: 
Traceback (most recent call last):
  File "D:/bin/chaoxing_auto_Shuake/com/main/Shuake.py", line 313, in get_chapters_info
    chapters_a = chapters_lxml.find_all(name="a")
AttributeError: 'NoneType' object has no attribute 'find_all'
2020-10-19 15:51:51,701 - Shuake.py[line:327] - INFO: 18182699011	获取chapter_info 失败
2020-10-19 15:51:51,780 - Shuake.py[line:326] - INFO: 
Traceback (most recent call last):
  File "D:/bin/chaoxing_auto_Shuake/com/main/Shuake.py", line 313, in get_chapters_info
    chapters_a = chapters_lxml.find_all(name="a")
AttributeError: 'NoneType' object has no attribute 'find_all'
2020-10-19 15:51:51,781 - Shuake.py[line:327] - INFO: 17561925661	获取chapter_info 失败
2020-10-19 15:56:23,583 - Shuake.py[line:270] - ERROR: 
Traceback (most recent call last):
  File "D:\ProgramData\Anaconda3\envs\spy\lib\site-packages\urllib3\connectionpool.py", line 600, in urlopen
    chunked=chunked)
  File "D:\ProgramData\Anaconda3\envs\spy\lib\site-packages\urllib3\connectionpool.py", line 384, in _make_request
    six.raise_from(e, None)
  File "<string>", line 2, in raise_from
  File "D:\ProgramData\Anaconda3\envs\spy\lib\site-packages\urllib3\connectionpool.py", line 380, in _make_request
    httplib_response = conn.getresponse()
  File "D:\ProgramData\Anaconda3\envs\spy\lib\http\client.py", line 1321, in getresponse
    response.begin()
  File "D:\ProgramData\Anaconda3\envs\spy\lib\http\client.py", line 296, in begin
    version, status, reason = self._read_status()
  File "D:\ProgramData\Anaconda3\envs\spy\lib\http\client.py", line 265, in _read_status
    raise RemoteDisconnected("Remote end closed connection without"
http.client.RemoteDisconnected: Remote end closed connection without response

During handling of the above exception, another exception occurred:

Traceback (most recent call last):
  File "D:\ProgramData\Anaconda3\envs\spy\lib\site-packages\requests\adapters.py", line 445, in send
    timeout=timeout
  File "D:\ProgramData\Anaconda3\envs\spy\lib\site-packages\urllib3\connectionpool.py", line 638, in urlopen
    _stacktrace=sys.exc_info()[2])
  File "D:\ProgramData\Anaconda3\envs\spy\lib\site-packages\urllib3\util\retry.py", line 367, in increment
    raise six.reraise(type(error), error, _stacktrace)
  File "D:\ProgramData\Anaconda3\envs\spy\lib\site-packages\urllib3\packages\six.py", line 685, in reraise
    raise value.with_traceback(tb)
  File "D:\ProgramData\Anaconda3\envs\spy\lib\site-packages\urllib3\connectionpool.py", line 600, in urlopen
    chunked=chunked)
  File "D:\ProgramData\Anaconda3\envs\spy\lib\site-packages\urllib3\connectionpool.py", line 384, in _make_request
    six.raise_from(e, None)
  File "<string>", line 2, in raise_from
  File "D:\ProgramData\Anaconda3\envs\spy\lib\site-packages\urllib3\connectionpool.py", line 380, in _make_request
    httplib_response = conn.getresponse()
  File "D:\ProgramData\Anaconda3\envs\spy\lib\http\client.py", line 1321, in getresponse
    response.begin()
  File "D:\ProgramData\Anaconda3\envs\spy\lib\http\client.py", line 296, in begin
    version, status, reason = self._read_status()
  File "D:\ProgramData\Anaconda3\envs\spy\lib\http\client.py", line 265, in _read_status
    raise RemoteDisconnected("Remote end closed connection without"
urllib3.exceptions.ProtocolError: ('Connection aborted.', RemoteDisconnected('Remote end closed connection without response'))

During handling of the above exception, another exception occurred:

Traceback (most recent call last):
  File "D:/bin/chaoxing_auto_Shuake/com/main/Shuake.py", line 232, in shuake
    params=params)
  File "D:\ProgramData\Anaconda3\envs\spy\lib\site-packages\requests\sessions.py", line 525, in get
    return self.request('GET', url, **kwargs)
  File "D:\ProgramData\Anaconda3\envs\spy\lib\site-packages\requests\sessions.py", line 512, in request
    resp = self.send(prep, **send_kwargs)
  File "D:\ProgramData\Anaconda3\envs\spy\lib\site-packages\requests\sessions.py", line 622, in send
    r = adapter.send(request, **kwargs)
  File "D:\ProgramData\Anaconda3\envs\spy\lib\site-packages\requests\adapters.py", line 495, in send
    raise ConnectionError(err, request=request)
requests.exceptions.ConnectionError: ('Connection aborted.', RemoteDisconnected('Remote end closed connection without response'))
2020-10-19 15:56:31,250 - Shuake.py[line:270] - ERROR: 
Traceback (most recent call last):
  File "D:\ProgramData\Anaconda3\envs\spy\lib\site-packages\urllib3\connectionpool.py", line 600, in urlopen
    chunked=chunked)
  File "D:\ProgramData\Anaconda3\envs\spy\lib\site-packages\urllib3\connectionpool.py", line 384, in _make_request
    six.raise_from(e, None)
  File "<string>", line 2, in raise_from
  File "D:\ProgramData\Anaconda3\envs\spy\lib\site-packages\urllib3\connectionpool.py", line 380, in _make_request
    httplib_response = conn.getresponse()
  File "D:\ProgramData\Anaconda3\envs\spy\lib\http\client.py", line 1321, in getresponse
    response.begin()
  File "D:\ProgramData\Anaconda3\envs\spy\lib\http\client.py", line 296, in begin
    version, status, reason = self._read_status()
  File "D:\ProgramData\Anaconda3\envs\spy\lib\http\client.py", line 257, in _read_status
    line = str(self.fp.readline(_MAXLINE + 1), "iso-8859-1")
  File "D:\ProgramData\Anaconda3\envs\spy\lib\socket.py", line 589, in readinto
    return self._sock.recv_into(b)
  File "D:\ProgramData\Anaconda3\envs\spy\lib\site-packages\urllib3\contrib\pyopenssl.py", line 290, in recv_into
    raise SocketError(str(e))
OSError: (10060, 'WSAETIMEDOUT')

During handling of the above exception, another exception occurred:

Traceback (most recent call last):
  File "D:\ProgramData\Anaconda3\envs\spy\lib\site-packages\requests\adapters.py", line 445, in send
    timeout=timeout
  File "D:\ProgramData\Anaconda3\envs\spy\lib\site-packages\urllib3\connectionpool.py", line 638, in urlopen
    _stacktrace=sys.exc_info()[2])
  File "D:\ProgramData\Anaconda3\envs\spy\lib\site-packages\urllib3\util\retry.py", line 367, in increment
    raise six.reraise(type(error), error, _stacktrace)
  File "D:\ProgramData\Anaconda3\envs\spy\lib\site-packages\urllib3\packages\six.py", line 685, in reraise
    raise value.with_traceback(tb)
  File "D:\ProgramData\Anaconda3\envs\spy\lib\site-packages\urllib3\connectionpool.py", line 600, in urlopen
    chunked=chunked)
  File "D:\ProgramData\Anaconda3\envs\spy\lib\site-packages\urllib3\connectionpool.py", line 384, in _make_request
    six.raise_from(e, None)
  File "<string>", line 2, in raise_from
  File "D:\ProgramData\Anaconda3\envs\spy\lib\site-packages\urllib3\connectionpool.py", line 380, in _make_request
    httplib_response = conn.getresponse()
  File "D:\ProgramData\Anaconda3\envs\spy\lib\http\client.py", line 1321, in getresponse
    response.begin()
  File "D:\ProgramData\Anaconda3\envs\spy\lib\http\client.py", line 296, in begin
    version, status, reason = self._read_status()
  File "D:\ProgramData\Anaconda3\envs\spy\lib\http\client.py", line 257, in _read_status
    line = str(self.fp.readline(_MAXLINE + 1), "iso-8859-1")
  File "D:\ProgramData\Anaconda3\envs\spy\lib\socket.py", line 589, in readinto
    return self._sock.recv_into(b)
  File "D:\ProgramData\Anaconda3\envs\spy\lib\site-packages\urllib3\contrib\pyopenssl.py", line 290, in recv_into
    raise SocketError(str(e))
urllib3.exceptions.ProtocolError: ('Connection aborted.', OSError("(10060, 'WSAETIMEDOUT')"))

During handling of the above exception, another exception occurred:

Traceback (most recent call last):
  File "D:/bin/chaoxing_auto_Shuake/com/main/Shuake.py", line 263, in shuake
    'https://special.zhexuezj.cn/special/course/addUserPoint', params=params)
  File "D:\ProgramData\Anaconda3\envs\spy\lib\site-packages\requests\sessions.py", line 525, in get
    return self.request('GET', url, **kwargs)
  File "D:\ProgramData\Anaconda3\envs\spy\lib\site-packages\requests\sessions.py", line 512, in request
    resp = self.send(prep, **send_kwargs)
  File "D:\ProgramData\Anaconda3\envs\spy\lib\site-packages\requests\sessions.py", line 622, in send
    r = adapter.send(request, **kwargs)
  File "D:\ProgramData\Anaconda3\envs\spy\lib\site-packages\requests\adapters.py", line 495, in send
    raise ConnectionError(err, request=request)
requests.exceptions.ConnectionError: ('Connection aborted.', OSError("(10060, 'WSAETIMEDOUT')"))
2020-10-19 15:56:32,007 - Shuake.py[line:270] - ERROR: 
Traceback (most recent call last):
  File "D:\ProgramData\Anaconda3\envs\spy\lib\site-packages\urllib3\connectionpool.py", line 600, in urlopen
    chunked=chunked)
  File "D:\ProgramData\Anaconda3\envs\spy\lib\site-packages\urllib3\connectionpool.py", line 384, in _make_request
    six.raise_from(e, None)
  File "<string>", line 2, in raise_from
  File "D:\ProgramData\Anaconda3\envs\spy\lib\site-packages\urllib3\connectionpool.py", line 380, in _make_request
    httplib_response = conn.getresponse()
  File "D:\ProgramData\Anaconda3\envs\spy\lib\http\client.py", line 1321, in getresponse
    response.begin()
  File "D:\ProgramData\Anaconda3\envs\spy\lib\http\client.py", line 296, in begin
    version, status, reason = self._read_status()
  File "D:\ProgramData\Anaconda3\envs\spy\lib\http\client.py", line 257, in _read_status
    line = str(self.fp.readline(_MAXLINE + 1), "iso-8859-1")
  File "D:\ProgramData\Anaconda3\envs\spy\lib\socket.py", line 589, in readinto
    return self._sock.recv_into(b)
  File "D:\ProgramData\Anaconda3\envs\spy\lib\site-packages\urllib3\contrib\pyopenssl.py", line 290, in recv_into
    raise SocketError(str(e))
OSError: (10060, 'WSAETIMEDOUT')

During handling of the above exception, another exception occurred:

Traceback (most recent call last):
  File "D:\ProgramData\Anaconda3\envs\spy\lib\site-packages\requests\adapters.py", line 445, in send
    timeout=timeout
  File "D:\ProgramData\Anaconda3\envs\spy\lib\site-packages\urllib3\connectionpool.py", line 638, in urlopen
    _stacktrace=sys.exc_info()[2])
  File "D:\ProgramData\Anaconda3\envs\spy\lib\site-packages\urllib3\util\retry.py", line 367, in increment
    raise six.reraise(type(error), error, _stacktrace)
  File "D:\ProgramData\Anaconda3\envs\spy\lib\site-packages\urllib3\packages\six.py", line 685, in reraise
    raise value.with_traceback(tb)
  File "D:\ProgramData\Anaconda3\envs\spy\lib\site-packages\urllib3\connectionpool.py", line 600, in urlopen
    chunked=chunked)
  File "D:\ProgramData\Anaconda3\envs\spy\lib\site-packages\urllib3\connectionpool.py", line 384, in _make_request
    six.raise_from(e, None)
  File "<string>", line 2, in raise_from
  File "D:\ProgramData\Anaconda3\envs\spy\lib\site-packages\urllib3\connectionpool.py", line 380, in _make_request
    httplib_response = conn.getresponse()
  File "D:\ProgramData\Anaconda3\envs\spy\lib\http\client.py", line 1321, in getresponse
    response.begin()
  File "D:\ProgramData\Anaconda3\envs\spy\lib\http\client.py", line 296, in begin
    version, status, reason = self._read_status()
  File "D:\ProgramData\Anaconda3\envs\spy\lib\http\client.py", line 257, in _read_status
    line = str(self.fp.readline(_MAXLINE + 1), "iso-8859-1")
  File "D:\ProgramData\Anaconda3\envs\spy\lib\socket.py", line 589, in readinto
    return self._sock.recv_into(b)
  File "D:\ProgramData\Anaconda3\envs\spy\lib\site-packages\urllib3\contrib\pyopenssl.py", line 290, in recv_into
    raise SocketError(str(e))
urllib3.exceptions.ProtocolError: ('Connection aborted.', OSError("(10060, 'WSAETIMEDOUT')"))

During handling of the above exception, another exception occurred:

Traceback (most recent call last):
  File "D:/bin/chaoxing_auto_Shuake/com/main/Shuake.py", line 263, in shuake
    'https://special.zhexuezj.cn/special/course/addUserPoint', params=params)
  File "D:\ProgramData\Anaconda3\envs\spy\lib\site-packages\requests\sessions.py", line 525, in get
    return self.request('GET', url, **kwargs)
  File "D:\ProgramData\Anaconda3\envs\spy\lib\site-packages\requests\sessions.py", line 512, in request
    resp = self.send(prep, **send_kwargs)
  File "D:\ProgramData\Anaconda3\envs\spy\lib\site-packages\requests\sessions.py", line 622, in send
    r = adapter.send(request, **kwargs)
  File "D:\ProgramData\Anaconda3\envs\spy\lib\site-packages\requests\adapters.py", line 495, in send
    raise ConnectionError(err, request=request)
requests.exceptions.ConnectionError: ('Connection aborted.', OSError("(10060, 'WSAETIMEDOUT')"))
2020-10-19 15:56:49,530 - Shuake.py[line:270] - ERROR: 
Traceback (most recent call last):
  File "D:\ProgramData\Anaconda3\envs\spy\lib\site-packages\urllib3\connectionpool.py", line 600, in urlopen
    chunked=chunked)
  File "D:\ProgramData\Anaconda3\envs\spy\lib\site-packages\urllib3\connectionpool.py", line 384, in _make_request
    six.raise_from(e, None)
  File "<string>", line 2, in raise_from
  File "D:\ProgramData\Anaconda3\envs\spy\lib\site-packages\urllib3\connectionpool.py", line 380, in _make_request
    httplib_response = conn.getresponse()
  File "D:\ProgramData\Anaconda3\envs\spy\lib\http\client.py", line 1321, in getresponse
    response.begin()
  File "D:\ProgramData\Anaconda3\envs\spy\lib\http\client.py", line 296, in begin
    version, status, reason = self._read_status()
  File "D:\ProgramData\Anaconda3\envs\spy\lib\http\client.py", line 265, in _read_status
    raise RemoteDisconnected("Remote end closed connection without"
http.client.RemoteDisconnected: Remote end closed connection without response

During handling of the above exception, another exception occurred:

Traceback (most recent call last):
  File "D:\ProgramData\Anaconda3\envs\spy\lib\site-packages\requests\adapters.py", line 445, in send
    timeout=timeout
  File "D:\ProgramData\Anaconda3\envs\spy\lib\site-packages\urllib3\connectionpool.py", line 638, in urlopen
    _stacktrace=sys.exc_info()[2])
  File "D:\ProgramData\Anaconda3\envs\spy\lib\site-packages\urllib3\util\retry.py", line 367, in increment
    raise six.reraise(type(error), error, _stacktrace)
  File "D:\ProgramData\Anaconda3\envs\spy\lib\site-packages\urllib3\packages\six.py", line 685, in reraise
    raise value.with_traceback(tb)
  File "D:\ProgramData\Anaconda3\envs\spy\lib\site-packages\urllib3\connectionpool.py", line 600, in urlopen
    chunked=chunked)
  File "D:\ProgramData\Anaconda3\envs\spy\lib\site-packages\urllib3\connectionpool.py", line 384, in _make_request
    six.raise_from(e, None)
  File "<string>", line 2, in raise_from
  File "D:\ProgramData\Anaconda3\envs\spy\lib\site-packages\urllib3\connectionpool.py", line 380, in _make_request
    httplib_response = conn.getresponse()
  File "D:\ProgramData\Anaconda3\envs\spy\lib\http\client.py", line 1321, in getresponse
    response.begin()
  File "D:\ProgramData\Anaconda3\envs\spy\lib\http\client.py", line 296, in begin
    version, status, reason = self._read_status()
  File "D:\ProgramData\Anaconda3\envs\spy\lib\http\client.py", line 265, in _read_status
    raise RemoteDisconnected("Remote end closed connection without"
urllib3.exceptions.ProtocolError: ('Connection aborted.', RemoteDisconnected('Remote end closed connection without response'))

During handling of the above exception, another exception occurred:

Traceback (most recent call last):
  File "D:/bin/chaoxing_auto_Shuake/com/main/Shuake.py", line 232, in shuake
    params=params)
  File "D:\ProgramData\Anaconda3\envs\spy\lib\site-packages\requests\sessions.py", line 525, in get
    return self.request('GET', url, **kwargs)
  File "D:\ProgramData\Anaconda3\envs\spy\lib\site-packages\requests\sessions.py", line 512, in request
    resp = self.send(prep, **send_kwargs)
  File "D:\ProgramData\Anaconda3\envs\spy\lib\site-packages\requests\sessions.py", line 622, in send
    r = adapter.send(request, **kwargs)
  File "D:\ProgramData\Anaconda3\envs\spy\lib\site-packages\requests\adapters.py", line 495, in send
    raise ConnectionError(err, request=request)
requests.exceptions.ConnectionError: ('Connection aborted.', RemoteDisconnected('Remote end closed connection without response'))
2020-10-19 15:56:54,213 - Shuake.py[line:270] - ERROR: 
Traceback (most recent call last):
  File "D:\ProgramData\Anaconda3\envs\spy\lib\site-packages\urllib3\connectionpool.py", line 600, in urlopen
    chunked=chunked)
  File "D:\ProgramData\Anaconda3\envs\spy\lib\site-packages\urllib3\connectionpool.py", line 384, in _make_request
    six.raise_from(e, None)
  File "<string>", line 2, in raise_from
  File "D:\ProgramData\Anaconda3\envs\spy\lib\site-packages\urllib3\connectionpool.py", line 380, in _make_request
    httplib_response = conn.getresponse()
  File "D:\ProgramData\Anaconda3\envs\spy\lib\http\client.py", line 1321, in getresponse
    response.begin()
  File "D:\ProgramData\Anaconda3\envs\spy\lib\http\client.py", line 296, in begin
    version, status, reason = self._read_status()
  File "D:\ProgramData\Anaconda3\envs\spy\lib\http\client.py", line 265, in _read_status
    raise RemoteDisconnected("Remote end closed connection without"
http.client.RemoteDisconnected: Remote end closed connection without response

During handling of the above exception, another exception occurred:

Traceback (most recent call last):
  File "D:\ProgramData\Anaconda3\envs\spy\lib\site-packages\requests\adapters.py", line 445, in send
    timeout=timeout
  File "D:\ProgramData\Anaconda3\envs\spy\lib\site-packages\urllib3\connectionpool.py", line 638, in urlopen
    _stacktrace=sys.exc_info()[2])
  File "D:\ProgramData\Anaconda3\envs\spy\lib\site-packages\urllib3\util\retry.py", line 367, in increment
    raise six.reraise(type(error), error, _stacktrace)
  File "D:\ProgramData\Anaconda3\envs\spy\lib\site-packages\urllib3\packages\six.py", line 685, in reraise
    raise value.with_traceback(tb)
  File "D:\ProgramData\Anaconda3\envs\spy\lib\site-packages\urllib3\connectionpool.py", line 600, in urlopen
    chunked=chunked)
  File "D:\ProgramData\Anaconda3\envs\spy\lib\site-packages\urllib3\connectionpool.py", line 384, in _make_request
    six.raise_from(e, None)
  File "<string>", line 2, in raise_from
  File "D:\ProgramData\Anaconda3\envs\spy\lib\site-packages\urllib3\connectionpool.py", line 380, in _make_request
    httplib_response = conn.getresponse()
  File "D:\ProgramData\Anaconda3\envs\spy\lib\http\client.py", line 1321, in getresponse
    response.begin()
  File "D:\ProgramData\Anaconda3\envs\spy\lib\http\client.py", line 296, in begin
    version, status, reason = self._read_status()
  File "D:\ProgramData\Anaconda3\envs\spy\lib\http\client.py", line 265, in _read_status
    raise RemoteDisconnected("Remote end closed connection without"
urllib3.exceptions.ProtocolError: ('Connection aborted.', RemoteDisconnected('Remote end closed connection without response'))

During handling of the above exception, another exception occurred:

Traceback (most recent call last):
  File "D:/bin/chaoxing_auto_Shuake/com/main/Shuake.py", line 232, in shuake
    params=params)
  File "D:\ProgramData\Anaconda3\envs\spy\lib\site-packages\requests\sessions.py", line 525, in get
    return self.request('GET', url, **kwargs)
  File "D:\ProgramData\Anaconda3\envs\spy\lib\site-packages\requests\sessions.py", line 512, in request
    resp = self.send(prep, **send_kwargs)
  File "D:\ProgramData\Anaconda3\envs\spy\lib\site-packages\requests\sessions.py", line 622, in send
    r = adapter.send(request, **kwargs)
  File "D:\ProgramData\Anaconda3\envs\spy\lib\site-packages\requests\adapters.py", line 495, in send
    raise ConnectionError(err, request=request)
requests.exceptions.ConnectionError: ('Connection aborted.', RemoteDisconnected('Remote end closed connection without response'))
2020-10-19 16:00:26,976 - Shuake.py[line:270] - ERROR: 
Traceback (most recent call last):
  File "D:/bin/chaoxing_auto_Shuake/com/main/Shuake.py", line 250, in shuake
    ponits = eval(re.search(r"points:'(.*?)'", response).group(1))
  File "<string>", line 0
    
    ^
SyntaxError: unexpected EOF while parsing
